[2025-10-19T21:41:53.951+0000] {local_task_job_runner.py:123} INFO - ::group::Pre task execution logs
[2025-10-19T21:41:53.991+0000] {taskinstance.py:2613} INFO - Dependencies all met for dep_context=non-requeueable deps ti=<TaskInstance: weekly_model_retraining.run_training_pipeline manual__2025-10-19T21:41:42.650573+00:00 [queued]>
[2025-10-19T21:41:54.007+0000] {taskinstance.py:2613} INFO - Dependencies all met for dep_context=requeueable deps ti=<TaskInstance: weekly_model_retraining.run_training_pipeline manual__2025-10-19T21:41:42.650573+00:00 [queued]>
[2025-10-19T21:41:54.008+0000] {taskinstance.py:2866} INFO - Starting attempt 1 of 3
[2025-10-19T21:41:54.028+0000] {taskinstance.py:2889} INFO - Executing <Task(DockerOperator): run_training_pipeline> on 2025-10-19 21:41:42.650573+00:00
[2025-10-19T21:41:54.045+0000] {standard_task_runner.py:72} INFO - Started process 705 to run task
[2025-10-19T21:41:54.051+0000] {standard_task_runner.py:104} INFO - Running: ['***', 'tasks', 'run', 'weekly_model_retraining', 'run_training_pipeline', 'manual__2025-10-19T21:41:42.650573+00:00', '--job-id', '4', '--raw', '--subdir', 'DAGS_FOLDER/weekly_retrain_dag.py', '--cfg-path', '/tmp/tmpc9igtx_e']
[2025-10-19T21:41:54.056+0000] {standard_task_runner.py:105} INFO - Job 4: Subtask run_training_pipeline
[2025-10-19T21:41:54.146+0000] {task_command.py:467} INFO - Running <TaskInstance: weekly_model_retraining.run_training_pipeline manual__2025-10-19T21:41:42.650573+00:00 [running]> on host 04677cc6273c
[2025-10-19T21:41:54.264+0000] {taskinstance.py:3132} INFO - Exporting env vars: AIRFLOW_CTX_DAG_EMAIL='team@example.com' AIRFLOW_CTX_DAG_OWNER='ml-team' AIRFLOW_CTX_DAG_ID='weekly_model_retraining' AIRFLOW_CTX_TASK_ID='run_training_pipeline' AIRFLOW_CTX_EXECUTION_DATE='2025-10-19T21:41:42.650573+00:00' AIRFLOW_CTX_TRY_NUMBER='1' AIRFLOW_CTX_DAG_RUN_ID='manual__2025-10-19T21:41:42.650573+00:00'
[2025-10-19T21:41:54.266+0000] {taskinstance.py:731} INFO - ::endgroup::
[2025-10-19T21:41:54.326+0000] {docker.py:379} INFO - Starting docker container from image fraud-detection:latest
[2025-10-19T21:43:00.831+0000] {docker.py:73} INFO - Traceback (most recent call last):
[2025-10-19T21:43:00.833+0000] {docker.py:73} INFO -   File "/usr/local/lib/python3.11/site-packages/urllib3/connection.py", line 198, in _new_conn
[2025-10-19T21:43:00.834+0000] {docker.py:73} INFO -     sock = connection.create_connection(
[2025-10-19T21:43:00.836+0000] {docker.py:73} INFO -            ^^^^^^^^^^^^^^^^^^^^^^^^^^^^^
[2025-10-19T21:43:00.836+0000] {docker.py:73} INFO -   File "/usr/local/lib/python3.11/site-packages/urllib3/util/connection.py", line 85, in create_connection
[2025-10-19T21:43:00.837+0000] {docker.py:73} INFO -     raise err
[2025-10-19T21:43:00.839+0000] {docker.py:73} INFO -   File "/usr/local/lib/python3.11/site-packages/urllib3/util/connection.py", line 73, in create_connection
[2025-10-19T21:43:00.840+0000] {docker.py:73} INFO -     sock.connect(sa)
[2025-10-19T21:43:00.841+0000] {docker.py:73} INFO - ConnectionRefusedError: [Errno 111] Connection refused
[2025-10-19T21:43:00.842+0000] {docker.py:73} INFO - 
[2025-10-19T21:43:00.843+0000] {docker.py:73} INFO - The above exception was the direct cause of the following exception:
[2025-10-19T21:43:00.844+0000] {docker.py:73} INFO - 
[2025-10-19T21:43:00.845+0000] {docker.py:73} INFO - Traceback (most recent call last):
[2025-10-19T21:43:00.846+0000] {docker.py:73} INFO -   File "/usr/local/lib/python3.11/site-packages/urllib3/connectionpool.py", line 787, in urlopen
[2025-10-19T21:43:00.847+0000] {docker.py:73} INFO -     response = self._make_request(
[2025-10-19T21:43:00.847+0000] {docker.py:73} INFO -                ^^^^^^^^^^^^^^^^^^^
[2025-10-19T21:43:00.848+0000] {docker.py:73} INFO -   File "/usr/local/lib/python3.11/site-packages/urllib3/connectionpool.py", line 493, in _make_request
[2025-10-19T21:43:00.849+0000] {docker.py:73} INFO -     conn.request(
[2025-10-19T21:43:00.849+0000] {docker.py:73} INFO -   File "/usr/local/lib/python3.11/site-packages/urllib3/connection.py", line 494, in request
[2025-10-19T21:43:00.850+0000] {docker.py:73} INFO -     self.endheaders()
[2025-10-19T21:43:00.851+0000] {docker.py:73} INFO -   File "/usr/local/lib/python3.11/http/client.py", line 1298, in endheaders
[2025-10-19T21:43:00.852+0000] {docker.py:73} INFO -     self._send_output(message_body, encode_chunked=encode_chunked)
[2025-10-19T21:43:00.853+0000] {docker.py:73} INFO -   File "/usr/local/lib/python3.11/http/client.py", line 1058, in _send_output
[2025-10-19T21:43:00.854+0000] {docker.py:73} INFO -     self.send(msg)
[2025-10-19T21:43:00.855+0000] {docker.py:73} INFO -   File "/usr/local/lib/python3.11/http/client.py", line 996, in send
[2025-10-19T21:43:00.855+0000] {docker.py:73} INFO -     self.connect()
[2025-10-19T21:43:00.856+0000] {docker.py:73} INFO -   File "/usr/local/lib/python3.11/site-packages/urllib3/connection.py", line 325, in connect
[2025-10-19T21:43:00.857+0000] {docker.py:73} INFO -     self.sock = self._new_conn()
[2025-10-19T21:43:00.858+0000] {docker.py:73} INFO -                 ^^^^^^^^^^^^^^^^
[2025-10-19T21:43:00.859+0000] {docker.py:73} INFO -   File "/usr/local/lib/python3.11/site-packages/urllib3/connection.py", line 213, in _new_conn
[2025-10-19T21:43:00.860+0000] {docker.py:73} INFO -     raise NewConnectionError(
[2025-10-19T21:43:00.860+0000] {docker.py:73} INFO - urllib3.exceptions.NewConnectionError: <urllib3.connection.HTTPConnection object at 0x78db09219bd0>: Failed to establish a new connection: [Errno 111] Connection refused
[2025-10-19T21:43:00.861+0000] {docker.py:73} INFO - 
[2025-10-19T21:43:00.862+0000] {docker.py:73} INFO - The above exception was the direct cause of the following exception:
[2025-10-19T21:43:00.864+0000] {docker.py:73} INFO - 
[2025-10-19T21:43:00.864+0000] {docker.py:73} INFO - Traceback (most recent call last):
[2025-10-19T21:43:00.865+0000] {docker.py:73} INFO -   File "/usr/local/lib/python3.11/site-packages/requests/adapters.py", line 644, in send
[2025-10-19T21:43:00.866+0000] {docker.py:73} INFO -     resp = conn.urlopen(
[2025-10-19T21:43:00.867+0000] {docker.py:73} INFO -            ^^^^^^^^^^^^^
[2025-10-19T21:43:00.868+0000] {docker.py:73} INFO -   File "/usr/local/lib/python3.11/site-packages/urllib3/connectionpool.py", line 871, in urlopen
[2025-10-19T21:43:00.869+0000] {docker.py:73} INFO -     return self.urlopen(
[2025-10-19T21:43:00.870+0000] {docker.py:73} INFO -            ^^^^^^^^^^^^^
[2025-10-19T21:43:00.870+0000] {docker.py:73} INFO -   File "/usr/local/lib/python3.11/site-packages/urllib3/connectionpool.py", line 871, in urlopen
[2025-10-19T21:43:00.871+0000] {docker.py:73} INFO -     return self.urlopen(
[2025-10-19T21:43:00.872+0000] {docker.py:73} INFO -            ^^^^^^^^^^^^^
[2025-10-19T21:43:00.873+0000] {docker.py:73} INFO -   File "/usr/local/lib/python3.11/site-packages/urllib3/connectionpool.py", line 871, in urlopen
[2025-10-19T21:43:00.873+0000] {docker.py:73} INFO -     return self.urlopen(
[2025-10-19T21:43:00.874+0000] {docker.py:73} INFO -            ^^^^^^^^^^^^^
[2025-10-19T21:43:00.875+0000] {docker.py:73} INFO -   [Previous line repeated 2 more times]
[2025-10-19T21:43:00.876+0000] {docker.py:73} INFO -   File "/usr/local/lib/python3.11/site-packages/urllib3/connectionpool.py", line 841, in urlopen
[2025-10-19T21:43:00.877+0000] {docker.py:73} INFO -     retries = retries.increment(
[2025-10-19T21:43:00.878+0000] {docker.py:73} INFO -               ^^^^^^^^^^^^^^^^^^
[2025-10-19T21:43:00.878+0000] {docker.py:73} INFO -   File "/usr/local/lib/python3.11/site-packages/urllib3/util/retry.py", line 519, in increment
[2025-10-19T21:43:00.879+0000] {docker.py:73} INFO -     raise MaxRetryError(_pool, url, reason) from reason  # type: ignore[arg-type]
[2025-10-19T21:43:00.880+0000] {docker.py:73} INFO -     ^^^^^^^^^^^^^^^^^^^^^^^^^^^^^^^^^^^^^^^^^^^^^^^^^^^
[2025-10-19T21:43:00.881+0000] {docker.py:73} INFO - urllib3.exceptions.MaxRetryError: HTTPConnectionPool(host='localhost', port=5000): Max retries exceeded with url: /api/2.0/mlflow/experiments/get-by-name?experiment_name=Fraud+Detection (Caused by NewConnectionError('<urllib3.connection.HTTPConnection object at 0x78db09219bd0>: Failed to establish a new connection: [Errno 111] Connection refused'))
[2025-10-19T21:43:00.882+0000] {docker.py:73} INFO - 
[2025-10-19T21:43:00.883+0000] {docker.py:73} INFO - During handling of the above exception, another exception occurred:
[2025-10-19T21:43:00.883+0000] {docker.py:73} INFO - 
[2025-10-19T21:43:00.884+0000] {docker.py:73} INFO - Traceback (most recent call last):
[2025-10-19T21:43:00.885+0000] {docker.py:73} INFO -   File "/usr/local/lib/python3.11/site-packages/mlflow/utils/rest_utils.py", line 189, in http_request
[2025-10-19T21:43:00.886+0000] {docker.py:73} INFO -     return _get_http_response_with_retries(
[2025-10-19T21:43:00.887+0000] {docker.py:73} INFO -            ^^^^^^^^^^^^^^^^^^^^^^^^^^^^^^^^
[2025-10-19T21:43:00.887+0000] {docker.py:73} INFO -   File "/usr/local/lib/python3.11/site-packages/mlflow/utils/request_utils.py", line 237, in _get_http_response_with_retries
[2025-10-19T21:43:00.888+0000] {docker.py:73} INFO -     return session.request(method, url, allow_redirects=allow_redirects, **kwargs)
[2025-10-19T21:43:00.889+0000] {docker.py:73} INFO -            ^^^^^^^^^^^^^^^^^^^^^^^^^^^^^^^^^^^^^^^^^^^^^^^^^^^^^^^^^^^^^^^^^^^^^^^
[2025-10-19T21:43:00.890+0000] {docker.py:73} INFO -   File "/usr/local/lib/python3.11/site-packages/requests/sessions.py", line 589, in request
[2025-10-19T21:43:00.891+0000] {docker.py:73} INFO -     resp = self.send(prep, **send_kwargs)
[2025-10-19T21:43:00.892+0000] {docker.py:73} INFO -            ^^^^^^^^^^^^^^^^^^^^^^^^^^^^^^
[2025-10-19T21:43:00.893+0000] {docker.py:73} INFO -   File "/usr/local/lib/python3.11/site-packages/requests/sessions.py", line 703, in send
[2025-10-19T21:43:00.894+0000] {docker.py:73} INFO -     r = adapter.send(request, **kwargs)
[2025-10-19T21:43:00.895+0000] {docker.py:73} INFO -         ^^^^^^^^^^^^^^^^^^^^^^^^^^^^^^^
[2025-10-19T21:43:00.895+0000] {docker.py:73} INFO -   File "/usr/local/lib/python3.11/site-packages/requests/adapters.py", line 677, in send
[2025-10-19T21:43:00.896+0000] {docker.py:73} INFO -     raise ConnectionError(e, request=request)
[2025-10-19T21:43:00.897+0000] {docker.py:73} INFO - requests.exceptions.ConnectionError: HTTPConnectionPool(host='localhost', port=5000): Max retries exceeded with url: /api/2.0/mlflow/experiments/get-by-name?experiment_name=Fraud+Detection (Caused by NewConnectionError('<urllib3.connection.HTTPConnection object at 0x78db09219bd0>: Failed to establish a new connection: [Errno 111] Connection refused'))
[2025-10-19T21:43:00.898+0000] {docker.py:73} INFO - 
[2025-10-19T21:43:00.898+0000] {docker.py:73} INFO - During handling of the above exception, another exception occurred:
[2025-10-19T21:43:00.900+0000] {docker.py:73} INFO - 
[2025-10-19T21:43:00.901+0000] {docker.py:73} INFO - Traceback (most recent call last):
[2025-10-19T21:43:00.902+0000] {docker.py:73} INFO -   File "<frozen runpy>", line 198, in _run_module_as_main
[2025-10-19T21:43:00.903+0000] {docker.py:73} INFO -   File "<frozen runpy>", line 88, in _run_code
[2025-10-19T21:43:00.903+0000] {docker.py:73} INFO -   File "/app/scripts/run_pipeline.py", line 24, in <module>
[2025-10-19T21:43:00.904+0000] {docker.py:73} INFO -     mlflow.set_experiment(EXPERIMENT_NAME)
[2025-10-19T21:43:00.905+0000] {docker.py:73} INFO -   File "/usr/local/lib/python3.11/site-packages/mlflow/tracking/fluent.py", line 145, in set_experiment
[2025-10-19T21:43:00.905+0000] {docker.py:73} INFO -     experiment = client.get_experiment_by_name(experiment_name)
[2025-10-19T21:43:00.906+0000] {docker.py:73} INFO -                  ^^^^^^^^^^^^^^^^^^^^^^^^^^^^^^^^^^^^^^^^^^^^^^
[2025-10-19T21:43:00.907+0000] {docker.py:73} INFO -   File "/usr/local/lib/python3.11/site-packages/mlflow/tracking/client.py", line 1249, in get_experiment_by_name
[2025-10-19T21:43:00.908+0000] {docker.py:73} INFO -     return self._tracking_client.get_experiment_by_name(name)
[2025-10-19T21:43:00.909+0000] {docker.py:73} INFO -            ^^^^^^^^^^^^^^^^^^^^^^^^^^^^^^^^^^^^^^^^^^^^^^^^^^
[2025-10-19T21:43:00.909+0000] {docker.py:73} INFO -   File "/usr/local/lib/python3.11/site-packages/mlflow/tracking/_tracking_service/client.py", line 484, in get_experiment_by_name
[2025-10-19T21:43:00.910+0000] {docker.py:73} INFO -     return self.store.get_experiment_by_name(name)
[2025-10-19T21:43:00.911+0000] {docker.py:73} INFO -            ^^^^^^^^^^^^^^^^^^^^^^^^^^^^^^^^^^^^^^^
[2025-10-19T21:43:00.912+0000] {docker.py:73} INFO -   File "/usr/local/lib/python3.11/site-packages/mlflow/store/tracking/rest_store.py", line 519, in get_experiment_by_name
[2025-10-19T21:43:00.913+0000] {docker.py:73} INFO -     response_proto = self._call_endpoint(GetExperimentByName, req_body)
[2025-10-19T21:43:00.914+0000] {docker.py:73} INFO -                      ^^^^^^^^^^^^^^^^^^^^^^^^^^^^^^^^^^^^^^^^^^^^^^^^^^
[2025-10-19T21:43:00.915+0000] {docker.py:73} INFO -   File "/usr/local/lib/python3.11/site-packages/mlflow/store/tracking/rest_store.py", line 82, in _call_endpoint
[2025-10-19T21:43:00.916+0000] {docker.py:73} INFO -     return call_endpoint(self.get_host_creds(), endpoint, method, json_body, response_proto)
[2025-10-19T21:43:00.916+0000] {docker.py:73} INFO -            ^^^^^^^^^^^^^^^^^^^^^^^^^^^^^^^^^^^^^^^^^^^^^^^^^^^^^^^^^^^^^^^^^^^^^^^^^^^^^^^^^
[2025-10-19T21:43:00.917+0000] {docker.py:73} INFO -   File "/usr/local/lib/python3.11/site-packages/mlflow/utils/rest_utils.py", line 365, in call_endpoint
[2025-10-19T21:43:00.918+0000] {docker.py:73} INFO -     response = http_request(**call_kwargs)
[2025-10-19T21:43:00.919+0000] {docker.py:73} INFO -                ^^^^^^^^^^^^^^^^^^^^^^^^^^^
[2025-10-19T21:43:00.920+0000] {docker.py:73} INFO -   File "/usr/local/lib/python3.11/site-packages/mlflow/utils/rest_utils.py", line 212, in http_request
[2025-10-19T21:43:00.921+0000] {docker.py:73} INFO -     raise MlflowException(f"API request to {url} failed with exception {e}")
[2025-10-19T21:43:00.922+0000] {docker.py:73} INFO - mlflow.exceptions.MlflowException: API request to http://localhost:5000/api/2.0/mlflow/experiments/get-by-name failed with exception HTTPConnectionPool(host='localhost', port=5000): Max retries exceeded with url: /api/2.0/mlflow/experiments/get-by-name?experiment_name=Fraud+Detection (Caused by NewConnectionError('<urllib3.connection.HTTPConnection object at 0x78db09219bd0>: Failed to establish a new connection: [Errno 111] Connection refused'))
[2025-10-19T21:43:01.585+0000] {taskinstance.py:3311} ERROR - Task failed with exception
Traceback (most recent call last):
  File "/home/airflow/.local/lib/python3.11/site-packages/airflow/models/taskinstance.py", line 767, in _execute_task
    result = _execute_callable(context=context, **execute_callable_kwargs)
             ^^^^^^^^^^^^^^^^^^^^^^^^^^^^^^^^^^^^^^^^^^^^^^^^^^^^^^^^^^^^^
  File "/home/airflow/.local/lib/python3.11/site-packages/airflow/models/taskinstance.py", line 733, in _execute_callable
    return ExecutionCallableRunner(
           ^^^^^^^^^^^^^^^^^^^^^^^^
  File "/home/airflow/.local/lib/python3.11/site-packages/airflow/utils/operator_helpers.py", line 252, in run
    return self.func(*args, **kwargs)
           ^^^^^^^^^^^^^^^^^^^^^^^^^^
  File "/home/airflow/.local/lib/python3.11/site-packages/airflow/models/baseoperator.py", line 422, in wrapper
    return func(self, *args, **kwargs)
           ^^^^^^^^^^^^^^^^^^^^^^^^^^^
  File "/home/airflow/.local/lib/python3.11/site-packages/airflow/providers/docker/operators/docker.py", line 519, in execute
    return self._run_image()
           ^^^^^^^^^^^^^^^^^
  File "/home/airflow/.local/lib/python3.11/site-packages/airflow/providers/docker/operators/docker.py", line 396, in _run_image
    return self._run_image_with_mounts(self.mounts, add_tmp_variable=False)
           ^^^^^^^^^^^^^^^^^^^^^^^^^^^^^^^^^^^^^^^^^^^^^^^^^^^^^^^^^^^^^^^^
  File "/home/airflow/.local/lib/python3.11/site-packages/airflow/providers/docker/operators/docker.py", line 453, in _run_image_with_mounts
    raise DockerContainerFailedException(f"Docker container failed: {result!r}", logs=log_lines)
airflow.providers.docker.exceptions.DockerContainerFailedException: Docker container failed: {'StatusCode': 1}
[2025-10-19T21:43:01.598+0000] {taskinstance.py:1225} INFO - Marking task as UP_FOR_RETRY. dag_id=weekly_model_retraining, task_id=run_training_pipeline, run_id=manual__2025-10-19T21:41:42.650573+00:00, execution_date=20251019T214142, start_date=20251019T214153, end_date=20251019T214301
[2025-10-19T21:43:01.625+0000] {taskinstance.py:340} INFO - ::group::Post task execution logs
[2025-10-19T21:43:01.626+0000] {standard_task_runner.py:124} ERROR - Failed to execute job 4 for task run_training_pipeline (Docker container failed: {'StatusCode': 1}; 705)
Traceback (most recent call last):
  File "/home/airflow/.local/lib/python3.11/site-packages/airflow/task/task_runner/standard_task_runner.py", line 117, in _start_by_fork
    ret = args.func(args, dag=self.dag)
          ^^^^^^^^^^^^^^^^^^^^^^^^^^^^^
  File "/home/airflow/.local/lib/python3.11/site-packages/airflow/cli/cli_config.py", line 49, in command
    return func(*args, **kwargs)
           ^^^^^^^^^^^^^^^^^^^^^
  File "/home/airflow/.local/lib/python3.11/site-packages/airflow/utils/cli.py", line 116, in wrapper
    return f(*args, **kwargs)
           ^^^^^^^^^^^^^^^^^^
  File "/home/airflow/.local/lib/python3.11/site-packages/airflow/cli/commands/task_command.py", line 483, in task_run
    task_return_code = _run_task_by_selected_method(args, _dag, ti)
                       ^^^^^^^^^^^^^^^^^^^^^^^^^^^^^^^^^^^^^^^^^^^^
  File "/home/airflow/.local/lib/python3.11/site-packages/airflow/cli/commands/task_command.py", line 256, in _run_task_by_selected_method
    return _run_raw_task(args, ti)
           ^^^^^^^^^^^^^^^^^^^^^^^
  File "/home/airflow/.local/lib/python3.11/site-packages/airflow/cli/commands/task_command.py", line 341, in _run_raw_task
    return ti._run_raw_task(
           ^^^^^^^^^^^^^^^^^
  File "/home/airflow/.local/lib/python3.11/site-packages/airflow/utils/session.py", line 97, in wrapper
    return func(*args, session=session, **kwargs)
           ^^^^^^^^^^^^^^^^^^^^^^^^^^^^^^^^^^^^^^
  File "/home/airflow/.local/lib/python3.11/site-packages/airflow/models/taskinstance.py", line 3005, in _run_raw_task
    return _run_raw_task(
           ^^^^^^^^^^^^^^
  File "/home/airflow/.local/lib/python3.11/site-packages/airflow/models/taskinstance.py", line 273, in _run_raw_task
    TaskInstance._execute_task_with_callbacks(
  File "/home/airflow/.local/lib/python3.11/site-packages/airflow/models/taskinstance.py", line 3159, in _execute_task_with_callbacks
    result = self._execute_task(context, task_orig)
             ^^^^^^^^^^^^^^^^^^^^^^^^^^^^^^^^^^^^^^
  File "/home/airflow/.local/lib/python3.11/site-packages/airflow/models/taskinstance.py", line 3183, in _execute_task
    return _execute_task(self, context, task_orig)
           ^^^^^^^^^^^^^^^^^^^^^^^^^^^^^^^^^^^^^^^
  File "/home/airflow/.local/lib/python3.11/site-packages/airflow/models/taskinstance.py", line 767, in _execute_task
    result = _execute_callable(context=context, **execute_callable_kwargs)
             ^^^^^^^^^^^^^^^^^^^^^^^^^^^^^^^^^^^^^^^^^^^^^^^^^^^^^^^^^^^^^
  File "/home/airflow/.local/lib/python3.11/site-packages/airflow/models/taskinstance.py", line 733, in _execute_callable
    return ExecutionCallableRunner(
           ^^^^^^^^^^^^^^^^^^^^^^^^
  File "/home/airflow/.local/lib/python3.11/site-packages/airflow/utils/operator_helpers.py", line 252, in run
    return self.func(*args, **kwargs)
           ^^^^^^^^^^^^^^^^^^^^^^^^^^
  File "/home/airflow/.local/lib/python3.11/site-packages/airflow/models/baseoperator.py", line 422, in wrapper
    return func(self, *args, **kwargs)
           ^^^^^^^^^^^^^^^^^^^^^^^^^^^
  File "/home/airflow/.local/lib/python3.11/site-packages/airflow/providers/docker/operators/docker.py", line 519, in execute
    return self._run_image()
           ^^^^^^^^^^^^^^^^^
  File "/home/airflow/.local/lib/python3.11/site-packages/airflow/providers/docker/operators/docker.py", line 396, in _run_image
    return self._run_image_with_mounts(self.mounts, add_tmp_variable=False)
           ^^^^^^^^^^^^^^^^^^^^^^^^^^^^^^^^^^^^^^^^^^^^^^^^^^^^^^^^^^^^^^^^
  File "/home/airflow/.local/lib/python3.11/site-packages/airflow/providers/docker/operators/docker.py", line 453, in _run_image_with_mounts
    raise DockerContainerFailedException(f"Docker container failed: {result!r}", logs=log_lines)
airflow.providers.docker.exceptions.DockerContainerFailedException: Docker container failed: {'StatusCode': 1}
[2025-10-19T21:43:01.685+0000] {local_task_job_runner.py:266} INFO - Task exited with return code 1
[2025-10-19T21:43:01.712+0000] {taskinstance.py:3895} INFO - 0 downstream tasks scheduled from follow-on schedule check
[2025-10-19T21:43:01.717+0000] {local_task_job_runner.py:245} INFO - ::endgroup::
